<?xml version="1.0" ?>
<!-- =================================================================================== -->
<!-- |    This document was autogenerated by xacro from robot.urdf                     | -->
<!-- |    EDITING THIS FILE BY HAND IS NOT RECOMMENDED                                 | -->
<!-- =================================================================================== -->
<!-- This URDF was automatically created by SolidWorks to URDF Exporter! Originally created by Stephen Brawner (brawner@gmail.com) 
     Commit Version: 1.6.0-4-g7f85cfe  Build Version: 1.6.7995.38578
     For more information, please see http://wiki.ros.org/sw_urdf_exporter -->
<robot name="Robot1" xmlns:xacro="http://ros.org/wiki/xacro">
<xacro:include filename="$(find urdf_test)/gazebo/robot.gazebo" />

  <link name="dummy">
    </link>

  <joint name="dummy_joint" type="fixed">
    <parent link="dummy"/>
    <child link="base_link"/>
  </joint>
  <link name="base_link">
    <inertial>
      <origin rpy="0 0 0" xyz="0.10774749511809 -0.0559414514988771 0.145140800944505"/>
      <mass value="1.93317068227308"/>
      <inertia ixx="0.00629448343170172" ixy="-1.15654709584654E-06" ixz="8.66235471435525E-07" iyy="0.00955087683924443" iyz="-5.69961069767612E-07" izz="0.00342079578442974"/>
    </inertial>
    <visual>
      <origin rpy="0 0 0" xyz="0 0 0"/>
      <geometry>
        <mesh filename="package://urdf_test/meshes/base_link.STL"/>
      </geometry>
      <material name="">
        <color rgba="0.898039215686275 0.917647058823529 0.929411764705882 1"/>
      </material>
    </visual>
    <collision>
      <origin rpy="0 0 0" xyz="0 0 0"/>
      <geometry>
        <mesh filename="package://urdf_test/meshes/base_link.STL"/>
      </geometry>
    </collision>
  </link>
  <link name="forward_right_link">
    <inertial>
      <origin rpy="0 0 0" xyz="0.004611 -1.5057E-05 6.1621E-06"/>
      <mass value="0.10206"/>
      <inertia ixx="0.00015483" ixy="-5.1182E-09" ixz="2.1324E-09" iyy="9.3209E-05" iyz="-1.9344E-09" izz="9.3205E-05"/>
    </inertial>
    <visual>
      <origin rpy="0 0 0" xyz="0 0 0"/>
      <geometry>
        <mesh filename="package://urdf_test/meshes/forward_right_link.STL"/>
      </geometry>
      <material name="">
        <color rgba="0.15294 0.15294 0.15294 1"/>
      </material>
    </visual>
    <collision>
      <origin rpy="0 0 0" xyz="0 0 0"/>
      <geometry>
        <mesh filename="package://urdf_test/meshes/forward_right_link.STL"/>
      </geometry>
    </collision>
  </link>
  <joint name="forward_right_joint" type="continuous">
    <origin rpy="-0.1216 0 3.1416" xyz="-0.045 -0.33465 -0.1125"/>
    <parent link="base_link"/>
    <child link="forward_right_link"/>
    <axis xyz="-1 0 0"/>
  </joint>
  <link name="forward_left_link">
    <inertial>
      <origin rpy="0 0 0" xyz="0.004611 -1.5057E-05 6.162E-06"/>
      <mass value="0.10206"/>
      <inertia ixx="0.00015483" ixy="-5.1182E-09" ixz="2.1324E-09" iyy="9.3209E-05" iyz="-1.9343E-09" izz="9.3205E-05"/>
    </inertial>
    <visual>
      <origin rpy="0 0 0" xyz="0 0 0"/>
      <geometry>
        <mesh filename="package://urdf_test/meshes/forward_left_link.STL"/>
      </geometry>
      <material name="">
        <color rgba="0.15294 0.15294 0.15294 1"/>
      </material>
    </visual>
    <collision>
      <origin rpy="0 0 0" xyz="0 0 0"/>
      <geometry>
        <mesh filename="package://urdf_test/meshes/forward_left_link.STL"/>
      </geometry>
    </collision>
  </link>
  <joint name="forward_left_joint" type="continuous">
    <origin rpy="-1.6924 0 0" xyz="0.26 -0.33465 -0.1125"/>
    <parent link="base_link"/>
    <child link="forward_left_link"/>
    <axis xyz="-1 0 0"/>
  </joint>
  <link name="back_right_link">
    <inertial>
      <origin rpy="0 0 0" xyz="0.004611 -1.5057E-05 6.162E-06"/>
      <mass value="0.10206"/>
      <inertia ixx="0.00015483" ixy="-5.1182E-09" ixz="2.1324E-09" iyy="9.3209E-05" iyz="-1.9343E-09" izz="9.3205E-05"/>
    </inertial>
    <visual>
      <origin rpy="0 0 0" xyz="0 0 0"/>
      <geometry>
        <mesh filename="package://urdf_test/meshes/back_right_link.STL"/>
      </geometry>
      <material name="">
        <color rgba="0.15294 0.15294 0.15294 1"/>
      </material>
    </visual>
    <collision>
      <origin rpy="0 0 0" xyz="0 0 0"/>
      <geometry>
        <mesh filename="package://urdf_test/meshes/back_right_link.STL"/>
      </geometry>
    </collision>
  </link>
  <joint name="back_right_joint" type="continuous">
    <origin rpy="-1.6924 0 3.1416" xyz="-0.045 0.034648 -0.1125"/>
    <parent link="base_link"/>
    <child link="back_right_link"/>
    <axis xyz="-1 0 0"/>
  </joint>
  <link name="back_left_link">
    <inertial>
      <origin rpy="0 0 0" xyz="0.00461096896086888 -1.50571685123765E-05 6.16205287674865E-06"/>
      <mass value="0.102063616339722"/>
      <inertia ixx="0.000154829800054215" ixy="-5.11824211938292E-09" ixz="2.13239728089323E-09" iyy="9.32089298816449E-05" iyz="-1.93431547079447E-09" izz="9.32050393197756E-05"/>
    </inertial>
    <visual>
      <origin rpy="0 0 0" xyz="0 0 0"/>
      <geometry>
        <mesh filename="package://urdf_test/meshes/back_left_link.STL"/>
      </geometry>
      <material name="">
        <color rgba="0.152941176470588 0.152941176470588 0.152941176470588 1"/>
      </material>
    </visual>
    <collision>
      <origin rpy="0 0 0" xyz="0 0 0"/>
      <geometry>
        <mesh filename="package://urdf_test/meshes/back_left_link.STL"/>
      </geometry>
    </collision>
  </link>
  <joint name="back_left_joint" type="continuous">
    <origin rpy="-0.1216 0 0" xyz="0.26 0.034648 -0.1125"/>
    <parent link="base_link"/>
    <child link="back_left_link"/>
    <axis xyz="-1 0 0"/>
  </joint>
</robot>
